I'm sorry, but an uncaught exception occurred.

While running game code:
  File "game/script.rpy", line 86, in script
    show dragonide_in_piedi at left with fade and umano_in_piedi
  File "game/script.rpy", line 86, in <module>
    show dragonide_in_piedi at left with fade and umano_in_piedi
NameError: name 'umano_in_piedi' is not defined

-- Full Traceback ------------------------------------------------------------

Full traceback:
  File "game/script.rpy", line 86, in script
    show dragonide_in_piedi at left with fade and umano_in_piedi
  File "C:\Users\Diego\Downloads\renpy-8.3.4-sdk\renpy\ast.py", line 1363, in execute
    paired = renpy.python.py_eval(self.paired)
  File "C:\Users\Diego\Downloads\renpy-8.3.4-sdk\renpy\python.py", line 1209, in py_eval
    return py_eval_bytecode(code, globals, locals)
  File "C:\Users\Diego\Downloads\renpy-8.3.4-sdk\renpy\python.py", line 1202, in py_eval_bytecode
    return eval(bytecode, globals, locals)
  File "game/script.rpy", line 86, in <module>
    show dragonide_in_piedi at left with fade and umano_in_piedi
NameError: name 'umano_in_piedi' is not defined

Windows-10-10.0.26100 AMD64
Ren'Py 8.3.4.24120703
progetto 1 1.0
Fri Jan 10 15:55:21 2025
